<sdf version='1.6'>
  <model name='simplicity'>
    <link name='base_link'>
      <pose frame=''>0 0 0 0 -0 0</pose>
      <inertial>
        <pose frame=''>0 -0.027758 0.016521 0 -0 0</pose>
        <mass>8.79859</mass>
        <inertia>
          <ixx>0.156556</ixx>
          <ixy>-1.09011e-08</ixy>
          <ixz>-5.39899e-08</ixz>
          <iyy>0.0233556</iyy>
          <iyz>0.0107079</iyz>
          <izz>0.162508</izz>
        </inertia>
      </inertial>
      <collision name='base_link_collision'>
        <pose frame=''>0 0 0 0 -0 0</pose>
        <geometry>
          <mesh>
            <scale>0.001 0.001 0.001</scale>
            <uri>model://simplicity_description/meshes/base_link.stl</uri>
          </mesh>
        </geometry>
        <surface>
          <contact>
            <ode/>
          </contact>
          <friction>
            <ode>
              <mu>0.2</mu>
              <mu2>0.2</mu2>
            </ode>
          </friction>
        </surface>
      </collision>
      <collision name='base_link_fixed_joint_lump__flap_1_collision_1'>
        <pose frame=''>0 0 0 0 -0 0</pose>
        <geometry>
          <mesh>
            <scale>0.001 0.001 0.001</scale>
            <uri>model://simplicity_description/meshes/flap_1.stl</uri>
          </mesh>
        </geometry>
        <surface>
          <contact>
            <ode/>
          </contact>
          <friction>
            <ode>
              <mu>0.2</mu>
              <mu2>0.2</mu2>
            </ode>
          </friction>
        </surface>
      </collision>
      <collision name='base_link_fixed_joint_lump__shoulder_link_ft_1_collision_2'>
        <pose frame=''>0 0 0 0 -0 0</pose>
        <geometry>
          <mesh>
            <scale>0.001 0.001 0.001</scale>
            <uri>model://simplicity_description/meshes/shoulder_link_ft_1.stl</uri>
          </mesh>
        </geometry>
        <surface>
          <contact>
            <ode/>
          </contact>
          <friction>
            <ode>
              <mu>0.2</mu>
              <mu2>0.2</mu2>
            </ode>
          </friction>
        </surface>
      </collision>
      <collision name='base_link_fixed_joint_lump__servo_shoulder_fl_1_collision_3'>
        <pose frame=''>0 0 0 0 -0 0</pose>
        <geometry>
          <mesh>
            <scale>0.001 0.001 0.001</scale>
            <uri>model://simplicity_description/meshes/servo_shoulder_fl_1.stl</uri>
          </mesh>
        </geometry>
        <surface>
          <contact>
            <ode/>
          </contact>
          <friction>
            <ode>
              <mu>0.2</mu>
              <mu2>0.2</mu2>
            </ode>
          </friction>
        </surface>
      </collision>
      <collision name='base_link_fixed_joint_lump__servo_back_fl_1_collision_4'>
        <pose frame=''>0 0 0 0 -0 0</pose>
        <geometry>
          <mesh>
            <scale>0.001 0.001 0.001</scale>
            <uri>model://simplicity_description/meshes/servo_back_fl_1.stl</uri>
          </mesh>
        </geometry>
        <surface>
          <contact>
            <ode/>
          </contact>
          <friction>
            <ode>
              <mu>0.2</mu>
              <mu2>0.2</mu2>
            </ode>
          </friction>
        </surface>
      </collision>
      <collision name='base_link_fixed_joint_lump__shoulder_link_fb_1_collision_5'>
        <pose frame=''>0 0 0 0 -0 0</pose>
        <geometry>
          <mesh>
            <scale>0.001 0.001 0.001</scale>
            <uri>model://simplicity_description/meshes/shoulder_link_fb_1.stl</uri>
          </mesh>
        </geometry>
        <surface>
          <contact>
            <ode/>
          </contact>
          <friction>
            <ode>
              <mu>0.2</mu>
              <mu2>0.2</mu2>
            </ode>
          </friction>
        </surface>
      </collision>
      <collision name='base_link_fixed_joint_lump__servo_shoulder_fr_1_collision_6'>
        <pose frame=''>-0 0 0 0 -0 0</pose>
        <geometry>
          <mesh>
            <scale>0.001 0.001 0.001</scale>
            <uri>model://simplicity_description/meshes/servo_shoulder_fr_1.stl</uri>
          </mesh>
        </geometry>
        <surface>
          <contact>
            <ode/>
          </contact>
          <friction>
            <ode>
              <mu>0.2</mu>
              <mu2>0.2</mu2>
            </ode>
          </friction>
        </surface>
      </collision>
      <collision name='base_link_fixed_joint_lump__servo_back_fr_1_collision_7'>
        <pose frame=''>-0 0 0 0 -0 0</pose>
        <geometry>
          <mesh>
            <scale>0.001 0.001 0.001</scale>
            <uri>model://simplicity_description/meshes/servo_back_fr_1.stl</uri>
          </mesh>
        </geometry>
        <surface>
          <contact>
            <ode/>
          </contact>
          <friction>
            <ode>
              <mu>0.2</mu>
              <mu2>0.2</mu2>
            </ode>
          </friction>
        </surface>
      </collision>
      <collision name='base_link_fixed_joint_lump__shoulder_link_bt_1_collision_8'>
        <pose frame=''>0 0 0 0 -0 0</pose>
        <geometry>
          <mesh>
            <scale>0.001 0.001 0.001</scale>
            <uri>model://simplicity_description/meshes/shoulder_link_bt_1.stl</uri>
          </mesh>
        </geometry>
        <surface>
          <contact>
            <ode/>
          </contact>
          <friction>
            <ode>
              <mu>0.2</mu>
              <mu2>0.2</mu2>
            </ode>
          </friction>
        </surface>
      </collision>
      <collision name='base_link_fixed_joint_lump__servo_shoulder_br_1_collision_9'>
        <pose frame=''>0 0 0 0 -0 0</pose>
        <geometry>
          <mesh>
            <scale>0.001 0.001 0.001</scale>
            <uri>model://simplicity_description/meshes/servo_shoulder_br_1.stl</uri>
          </mesh>
        </geometry>
        <surface>
          <contact>
            <ode/>
          </contact>
          <friction>
            <ode>
              <mu>0.2</mu>
              <mu2>0.2</mu2>
            </ode>
          </friction>
        </surface>
      </collision>
      <collision name='base_link_fixed_joint_lump__servo_back_br_1_collision_10'>
        <pose frame=''>0 0 0 0 -0 0</pose>
        <geometry>
          <mesh>
            <scale>0.001 0.001 0.001</scale>
            <uri>model://simplicity_description/meshes/servo_back_br_1.stl</uri>
          </mesh>
        </geometry>
        <surface>
          <contact>
            <ode/>
          </contact>
          <friction>
            <ode>
              <mu>0.2</mu>
              <mu2>0.2</mu2>
            </ode>
          </friction>
        </surface>
      </collision>
      <collision name='base_link_fixed_joint_lump__servo_shoulder_bl_1_collision_11'>
        <pose frame=''>0 0 0 0 -0 0</pose>
        <geometry>
          <mesh>
            <scale>0.001 0.001 0.001</scale>
            <uri>model://simplicity_description/meshes/servo_shoulder_bl_1.stl</uri>
          </mesh>
        </geometry>
        <surface>
          <contact>
            <ode/>
          </contact>
          <friction>
            <ode>
              <mu>0.2</mu>
              <mu2>0.2</mu2>
            </ode>
          </friction>
        </surface>
      </collision>
      <collision name='base_link_fixed_joint_lump__servo_back_bl_1_collision_12'>
        <pose frame=''>0 0 0 0 -0 0</pose>
        <geometry>
          <mesh>
            <scale>0.001 0.001 0.001</scale>
            <uri>model://simplicity_description/meshes/servo_back_bl_1.stl</uri>
          </mesh>
        </geometry>
        <surface>
          <contact>
            <ode/>
          </contact>
          <friction>
            <ode>
              <mu>0.2</mu>
              <mu2>0.2</mu2>
            </ode>
          </friction>
        </surface>
      </collision>
      <collision name='base_link_fixed_joint_lump__shoulder_link_bb_1_collision_13'>
        <pose frame=''>0 0 0 0 -0 0</pose>
        <geometry>
          <mesh>
            <scale>0.001 0.001 0.001</scale>
            <uri>model://simplicity_description/meshes/shoulder_link_bb_1.stl</uri>
          </mesh>
        </geometry>
        <surface>
          <contact>
            <ode/>
          </contact>
          <friction>
            <ode>
              <mu>0.2</mu>
              <mu2>0.2</mu2>
            </ode>
          </friction>
        </surface>
      </collision>
      <visual name='base_link_visual'>
        <pose frame=''>0 0 0 0 -0 0</pose>
        <geometry>
          <mesh>
            <scale>0.001 0.001 0.001</scale>
            <uri>model://simplicity_description/meshes/base_link.stl</uri>
          </mesh>
        </geometry>
        <material>
          <script>
            <name>Gazebo/Silver</name>
            <uri>file://media/materials/scripts/gazebo.material</uri>
          </script>
        </material>
      </visual>
      <visual name='base_link_fixed_joint_lump__flap_1_visual_1'>
        <pose frame=''>0 0 0 0 -0 0</pose>
        <geometry>
          <mesh>
            <scale>0.001 0.001 0.001</scale>
            <uri>model://simplicity_description/meshes/flap_1.stl</uri>
          </mesh>
        </geometry>
        <material>
          <script>
            <name>Gazebo/Silver</name>
            <uri>file://media/materials/scripts/gazebo.material</uri>
          </script>
        </material>
      </visual>
      <visual name='base_link_fixed_joint_lump__shoulder_link_ft_1_visual_2'>
        <pose frame=''>0 0 0 0 -0 0</pose>
        <geometry>
          <mesh>
            <scale>0.001 0.001 0.001</scale>
            <uri>model://simplicity_description/meshes/shoulder_link_ft_1.stl</uri>
          </mesh>
        </geometry>
        <material>
          <script>
            <name>Gazebo/Silver</name>
            <uri>file://media/materials/scripts/gazebo.material</uri>
          </script>
        </material>
      </visual>
      <visual name='base_link_fixed_joint_lump__servo_shoulder_fl_1_visual_3'>
        <pose frame=''>0 0 0 0 -0 0</pose>
        <geometry>
          <mesh>
            <scale>0.001 0.001 0.001</scale>
            <uri>model://simplicity_description/meshes/servo_shoulder_fl_1.stl</uri>
          </mesh>
        </geometry>
        <material>
          <script>
            <name>Gazebo/Silver</name>
            <uri>file://media/materials/scripts/gazebo.material</uri>
          </script>
        </material>
      </visual>
      <visual name='base_link_fixed_joint_lump__servo_back_fl_1_visual_4'>
        <pose frame=''>0 0 0 0 -0 0</pose>
        <geometry>
          <mesh>
            <scale>0.001 0.001 0.001</scale>
            <uri>model://simplicity_description/meshes/servo_back_fl_1.stl</uri>
          </mesh>
        </geometry>
        <material>
          <script>
            <name>Gazebo/Silver</name>
            <uri>file://media/materials/scripts/gazebo.material</uri>
          </script>
        </material>
      </visual>
      <visual name='base_link_fixed_joint_lump__shoulder_link_fb_1_visual_5'>
        <pose frame=''>0 0 0 0 -0 0</pose>
        <geometry>
          <mesh>
            <scale>0.001 0.001 0.001</scale>
            <uri>model://simplicity_description/meshes/shoulder_link_fb_1.stl</uri>
          </mesh>
        </geometry>
        <material>
          <script>
            <name>Gazebo/Silver</name>
            <uri>file://media/materials/scripts/gazebo.material</uri>
          </script>
        </material>
      </visual>
      <visual name='base_link_fixed_joint_lump__servo_shoulder_fr_1_visual_6'>
        <pose frame=''>-0 0 0 0 -0 0</pose>
        <geometry>
          <mesh>
            <scale>0.001 0.001 0.001</scale>
            <uri>model://simplicity_description/meshes/servo_shoulder_fr_1.stl</uri>
          </mesh>
        </geometry>
        <material>
          <script>
            <name>Gazebo/Silver</name>
            <uri>file://media/materials/scripts/gazebo.material</uri>
          </script>
        </material>
      </visual>
      <visual name='base_link_fixed_joint_lump__servo_back_fr_1_visual_7'>
        <pose frame=''>-0 0 0 0 -0 0</pose>
        <geometry>
          <mesh>
            <scale>0.001 0.001 0.001</scale>
            <uri>model://simplicity_description/meshes/servo_back_fr_1.stl</uri>
          </mesh>
        </geometry>
        <material>
          <script>
            <name>Gazebo/Silver</name>
            <uri>file://media/materials/scripts/gazebo.material</uri>
          </script>
        </material>
      </visual>
      <visual name='base_link_fixed_joint_lump__shoulder_link_bt_1_visual_8'>
        <pose frame=''>0 0 0 0 -0 0</pose>
        <geometry>
          <mesh>
            <scale>0.001 0.001 0.001</scale>
            <uri>model://simplicity_description/meshes/shoulder_link_bt_1.stl</uri>
          </mesh>
        </geometry>
        <material>
          <script>
            <name>Gazebo/Silver</name>
            <uri>file://media/materials/scripts/gazebo.material</uri>
          </script>
        </material>
      </visual>
      <visual name='base_link_fixed_joint_lump__servo_shoulder_br_1_visual_9'>
        <pose frame=''>0 0 0 0 -0 0</pose>
        <geometry>
          <mesh>
            <scale>0.001 0.001 0.001</scale>
            <uri>model://simplicity_description/meshes/servo_shoulder_br_1.stl</uri>
          </mesh>
        </geometry>
        <material>
          <script>
            <name>Gazebo/Silver</name>
            <uri>file://media/materials/scripts/gazebo.material</uri>
          </script>
        </material>
      </visual>
      <visual name='base_link_fixed_joint_lump__servo_back_br_1_visual_10'>
        <pose frame=''>0 0 0 0 -0 0</pose>
        <geometry>
          <mesh>
            <scale>0.001 0.001 0.001</scale>
            <uri>model://simplicity_description/meshes/servo_back_br_1.stl</uri>
          </mesh>
        </geometry>
        <material>
          <script>
            <name>Gazebo/Silver</name>
            <uri>file://media/materials/scripts/gazebo.material</uri>
          </script>
        </material>
      </visual>
      <visual name='base_link_fixed_joint_lump__servo_shoulder_bl_1_visual_11'>
        <pose frame=''>0 0 0 0 -0 0</pose>
        <geometry>
          <mesh>
            <scale>0.001 0.001 0.001</scale>
            <uri>model://simplicity_description/meshes/servo_shoulder_bl_1.stl</uri>
          </mesh>
        </geometry>
        <material>
          <script>
            <name>Gazebo/Silver</name>
            <uri>file://media/materials/scripts/gazebo.material</uri>
          </script>
        </material>
      </visual>
      <visual name='base_link_fixed_joint_lump__servo_back_bl_1_visual_12'>
        <pose frame=''>0 0 0 0 -0 0</pose>
        <geometry>
          <mesh>
            <scale>0.001 0.001 0.001</scale>
            <uri>model://simplicity_description/meshes/servo_back_bl_1.stl</uri>
          </mesh>
        </geometry>
        <material>
          <script>
            <name>Gazebo/Silver</name>
            <uri>file://media/materials/scripts/gazebo.material</uri>
          </script>
        </material>
      </visual>
      <visual name='base_link_fixed_joint_lump__shoulder_link_bb_1_visual_13'>
        <pose frame=''>0 0 0 0 -0 0</pose>
        <geometry>
          <mesh>
            <scale>0.001 0.001 0.001</scale>
            <uri>model://simplicity_description/meshes/shoulder_link_bb_1.stl</uri>
          </mesh>
        </geometry>
        <material>
          <script>
            <name>Gazebo/Silver</name>
            <uri>file://media/materials/scripts/gazebo.material</uri>
          </script>
        </material>
      </visual>
      <velocity_decay/>
      <velocity_decay/>
      <velocity_decay/>
      <velocity_decay/>
      <velocity_decay/>
      <velocity_decay/>
      <velocity_decay/>
      <velocity_decay/>
      <velocity_decay/>
      <velocity_decay/>
      <velocity_decay/>
      <velocity_decay/>
      <gravity>1</gravity>
      <velocity_decay/>
      <gravity>1</gravity>
      <velocity_decay/>
      <self_collide>1</self_collide>
    </link>
    <link name='shoulder_thigh_fl_1'>
      <pose frame=''>0.02 -0.2175 0.016284 0 -0 0</pose>
      <inertial>
        <pose frame=''>0.035368 0.018568 0 0 -0 0</pose>
        <mass>0.130474</mass>
        <inertia>
          <ixx>7.1e-05</ixx>
          <ixy>-7e-06</ixy>
          <ixz>-0</ixz>
          <iyy>5.6e-05</iyy>
          <iyz>-0</iyz>
          <izz>0.000123</izz>
        </inertia>
      </inertial>
      <collision name='shoulder_thigh_fl_1_collision'>
        <pose frame=''>-0.02 0.2175 -0.016284 0 -0 0</pose>
        <geometry>
          <mesh>
            <scale>0.001 0.001 0.001</scale>
            <uri>model://simplicity_description/meshes/shoulder_thigh_fl_1.stl</uri>
          </mesh>
        </geometry>
        <surface>
          <contact>
            <ode/>
          </contact>
          <friction>
            <ode>
              <mu>0.2</mu>
              <mu2>0.2</mu2>
            </ode>
          </friction>
        </surface>
      </collision>
      <visual name='shoulder_thigh_fl_1_visual'>
        <pose frame=''>-0.02 0.2175 -0.016284 0 -0 0</pose>
        <geometry>
          <mesh>
            <scale>0.001 0.001 0.001</scale>
            <uri>model://simplicity_description/meshes/shoulder_thigh_fl_1.stl</uri>
          </mesh>
        </geometry>
        <material>
          <script>
            <name>Gazebo/Silver</name>
            <uri>file://media/materials/scripts/gazebo.material</uri>
          </script>
        </material>
      </visual>
      <gravity>1</gravity>
      <velocity_decay/>
      <self_collide>1</self_collide>
    </link>
    <joint name='Rev15' type='revolute'>
      <child>shoulder_thigh_fl_1</child>
      <parent>base_link</parent>
      <axis>
        <xyz>0 -1 0</xyz>
        <limit>
          <lower>-1e+16</lower>
          <upper>1e+16</upper>
        </limit>
        <dynamics>
          <spring_reference>0</spring_reference>
          <spring_stiffness>0</spring_stiffness>
        </dynamics>
        <use_parent_model_frame>1</use_parent_model_frame>
      </axis>
    </joint>
    <link name='servo_thigh_fl_1'>
      <pose frame=''>0.07975 -0.19495 0.016284 0 -0 0</pose>
      <inertial>
        <pose frame=''>0.027076 0.035793 -0.035793 0 -0 0</pose>
        <mass>0.955761</mass>
        <inertia>
          <ixx>0.00189487</ixx>
          <ixy>-3.15807e-05</ixy>
          <ixz>3.15805e-05</ixz>
          <iyy>0.00102823</iyy>
          <iyz>0.000818937</iyz>
          <izz>0.00102823</izz>
        </inertia>
      </inertial>
      <collision name='servo_thigh_fl_1_collision'>
        <pose frame=''>-0.07975 0.19495 -0.016284 0 -0 0</pose>
        <geometry>
          <mesh>
            <scale>0.001 0.001 0.001</scale>
            <uri>model://simplicity_description/meshes/servo_thigh_fl_1.stl</uri>
          </mesh>
        </geometry>
        <surface>
          <contact>
            <ode/>
          </contact>
          <friction>
            <ode>
              <mu>0.2</mu>
              <mu2>0.2</mu2>
            </ode>
          </friction>
        </surface>
      </collision>
      <collision name='servo_thigh_fl_1_fixed_joint_lump__thigh_fl_1_collision_1'>
        <pose frame=''>-0.07975 0.19495 -0.016284 0 -0 0</pose>
        <geometry>
          <mesh>
            <scale>0.001 0.001 0.001</scale>
            <uri>model://simplicity_description/meshes/thigh_fl_1.stl</uri>
          </mesh>
        </geometry>
        <surface>
          <contact>
            <ode/>
          </contact>
          <friction>
            <ode>
              <mu>0.2</mu>
              <mu2>0.2</mu2>
            </ode>
          </friction>
        </surface>
      </collision>
      <collision name='servo_thigh_fl_1_fixed_joint_lump__servo_leg_fl_1_collision_2'>
        <pose frame=''>-0.07975 0.19495 -0.016284 0 -0 0</pose>
        <geometry>
          <mesh>
            <scale>0.001 0.001 0.001</scale>
            <uri>model://simplicity_description/meshes/servo_leg_fl_1.stl</uri>
          </mesh>
        </geometry>
        <surface>
          <contact>
            <ode/>
          </contact>
          <friction>
            <ode>
              <mu>0.2</mu>
              <mu2>0.2</mu2>
            </ode>
          </friction>
        </surface>
      </collision>
      <collision name='servo_thigh_fl_1_fixed_joint_lump__servo_leg_back_fl_1_collision_3'>
        <pose frame=''>-0.07975 0.19495 -0.016284 0 -0 0</pose>
        <geometry>
          <mesh>
            <scale>0.001 0.001 0.001</scale>
            <uri>model://simplicity_description/meshes/servo_leg_back_fl_1.stl</uri>
          </mesh>
        </geometry>
        <surface>
          <contact>
            <ode/>
          </contact>
          <friction>
            <ode>
              <mu>0.2</mu>
              <mu2>0.2</mu2>
            </ode>
          </friction>
        </surface>
      </collision>
      <visual name='servo_thigh_fl_1_visual'>
        <pose frame=''>-0.07975 0.19495 -0.016284 0 -0 0</pose>
        <geometry>
          <mesh>
            <scale>0.001 0.001 0.001</scale>
            <uri>model://simplicity_description/meshes/servo_thigh_fl_1.stl</uri>
          </mesh>
        </geometry>
        <material>
          <script>
            <name>Gazebo/Silver</name>
            <uri>file://media/materials/scripts/gazebo.material</uri>
          </script>
        </material>
      </visual>
      <visual name='servo_thigh_fl_1_fixed_joint_lump__thigh_fl_1_visual_1'>
        <pose frame=''>-0.07975 0.19495 -0.016284 0 -0 0</pose>
        <geometry>
          <mesh>
            <scale>0.001 0.001 0.001</scale>
            <uri>model://simplicity_description/meshes/thigh_fl_1.stl</uri>
          </mesh>
        </geometry>
        <material>
          <script>
            <name>Gazebo/Silver</name>
            <uri>file://media/materials/scripts/gazebo.material</uri>
          </script>
        </material>
      </visual>
      <visual name='servo_thigh_fl_1_fixed_joint_lump__servo_leg_fl_1_visual_2'>
        <pose frame=''>-0.07975 0.19495 -0.016284 0 -0 0</pose>
        <geometry>
          <mesh>
            <scale>0.001 0.001 0.001</scale>
            <uri>model://simplicity_description/meshes/servo_leg_fl_1.stl</uri>
          </mesh>
        </geometry>
        <material>
          <script>
            <name>Gazebo/Silver</name>
            <uri>file://media/materials/scripts/gazebo.material</uri>
          </script>
        </material>
      </visual>
      <visual name='servo_thigh_fl_1_fixed_joint_lump__servo_leg_back_fl_1_visual_3'>
        <pose frame=''>-0.07975 0.19495 -0.016284 0 -0 0</pose>
        <geometry>
          <mesh>
            <scale>0.001 0.001 0.001</scale>
            <uri>model://simplicity_description/meshes/servo_leg_back_fl_1.stl</uri>
          </mesh>
        </geometry>
        <material>
          <script>
            <name>Gazebo/Silver</name>
            <uri>file://media/materials/scripts/gazebo.material</uri>
          </script>
        </material>
      </visual>
      <velocity_decay/>
      <velocity_decay/>
      <velocity_decay/>
      <gravity>1</gravity>
      <velocity_decay/>
      <self_collide>1</self_collide>
    </link>
    <joint name='Rev18' type='revolute'>
      <child>servo_thigh_fl_1</child>
      <parent>shoulder_thigh_fl_1</parent>
      <axis>
        <xyz>-1 0 0</xyz>
        <limit>
          <lower>-1e+16</lower>
          <upper>1e+16</upper>
        </limit>
        <dynamics>
          <spring_reference>0</spring_reference>
          <spring_stiffness>0</spring_stiffness>
        </dynamics>
        <use_parent_model_frame>1</use_parent_model_frame>
      </axis>
    </joint>
    <link name='thigh_leg_fl_1'>
      <pose frame=''>0.13475 -0.125349 -0.053317 0 -0 0</pose>
      <inertial>
        <pose frame=''>-0.020847 -0.033398 -0.061377 0 -0 0</pose>
        <mass>0.28447</mass>
        <inertia>
          <ixx>0.000444752</ixx>
          <ixy>-1.19327e-05</ixy>
          <ixz>-2.232e-05</ixz>
          <iyy>0.000430302</iyy>
          <iyz>-0.000175334</iyz>
          <izz>0.000170212</izz>
        </inertia>
      </inertial>
      <collision name='thigh_leg_fl_1_collision'>
        <pose frame=''>-0.13475 0.125349 0.053317 0 -0 0</pose>
        <geometry>
          <mesh>
            <scale>0.001 0.001 0.001</scale>
            <uri>model://simplicity_description/meshes/thigh_leg_fl_1.stl</uri>
          </mesh>
        </geometry>
        <surface>
          <contact>
            <ode/>
          </contact>
          <friction>
            <ode>
              <mu>0.2</mu>
              <mu2>0.2</mu2>
            </ode>
          </friction>
        </surface>
      </collision>
      <collision name='thigh_leg_fl_1_fixed_joint_lump__contact_sensor_fl_1_collision_1'>
        <pose frame=''>-0.13475 0.125349 0.053317 0 -0 0</pose>
        <geometry>
          <mesh>
            <scale>0.001 0.001 0.001</scale>
            <uri>model://simplicity_description/meshes/contact_sensor_fl_1.stl</uri>
          </mesh>
        </geometry>
        <surface>
          <contact>
            <ode>
              <kp>1e+06</kp>
              <kd>1e+06</kd>
            </ode>
          </contact>
          <friction>
            <ode>
              <mu>1e+06</mu>
              <mu2>1e+06</mu2>
            </ode>
          </friction>
        </surface>
      </collision>
      <collision name='thigh_leg_fl_1_fixed_joint_lump__leg_fl_1_collision_2'>
        <pose frame=''>-0.13475 0.125349 0.053317 0 -0 0</pose>
        <geometry>
          <mesh>
            <scale>0.001 0.001 0.001</scale>
            <uri>model://simplicity_description/meshes/leg_fl_1.stl</uri>
          </mesh>
        </geometry>
        <surface>
          <contact>
            <ode/>
          </contact>
          <friction>
            <ode>
              <mu>0.2</mu>
              <mu2>0.2</mu2>
            </ode>
          </friction>
        </surface>
      </collision>
      <visual name='thigh_leg_fl_1_visual'>
        <pose frame=''>-0.13475 0.125349 0.053317 0 -0 0</pose>
        <geometry>
          <mesh>
            <scale>0.001 0.001 0.001</scale>
            <uri>model://simplicity_description/meshes/thigh_leg_fl_1.stl</uri>
          </mesh>
        </geometry>
        <material>
          <script>
            <name>Gazebo/Silver</name>
            <uri>file://media/materials/scripts/gazebo.material</uri>
          </script>
        </material>
      </visual>
      <visual name='thigh_leg_fl_1_fixed_joint_lump__contact_sensor_fl_1_visual_1'>
        <pose frame=''>-0.13475 0.125349 0.053317 0 -0 0</pose>
        <geometry>
          <mesh>
            <scale>0.001 0.001 0.001</scale>
            <uri>model://simplicity_description/meshes/contact_sensor_fl_1.stl</uri>
          </mesh>
        </geometry>
        <material>
          <script>
            <name>Gazebo/Blue</name>
            <uri>file://media/materials/scripts/gazebo.material</uri>
          </script>
        </material>
      </visual>
      <visual name='thigh_leg_fl_1_fixed_joint_lump__leg_fl_1_visual_2'>
        <pose frame=''>-0.13475 0.125349 0.053317 0 -0 0</pose>
        <geometry>
          <mesh>
            <scale>0.001 0.001 0.001</scale>
            <uri>model://simplicity_description/meshes/leg_fl_1.stl</uri>
          </mesh>
        </geometry>
        <material>
          <script>
            <name>Gazebo/Silver</name>
            <uri>file://media/materials/scripts/gazebo.material</uri>
          </script>
        </material>
      </visual>
      <velocity_decay/>
      <velocity_decay/>
      <velocity_decay/>
      <sensor name='contactsensor_sensor' type='contact'>
        <always_on>1</always_on>
        <contact>
          <collision>contact_sensor_fl_1_collision_1</collision>
          <topic>__default_topic__</topic>
        </contact>
        <plugin name='bumper0_plugin' filename='libgazebo_ros_bumper.so'>
          <bumperTopicName>front_left_contact_sensor_state</bumperTopicName>
          <frameName>contact_sensor_fl_1</frameName>
        </plugin>
        <pose frame=''>-0.012707 -0.028468 -0.049355 0 -0 0</pose>
      </sensor>
      <gravity>1</gravity>
      <velocity_decay/>
      <self_collide>1</self_collide>
    </link>
    <joint name='Rev35' type='revolute'>
      <child>thigh_leg_fl_1</child>
      <parent>servo_thigh_fl_1</parent>
      <axis>
        <xyz>1 0 0</xyz>
        <limit>
          <lower>-1e+16</lower>
          <upper>1e+16</upper>
        </limit>
        <dynamics>
          <spring_reference>0</spring_reference>
          <spring_stiffness>0</spring_stiffness>
        </dynamics>
        <use_parent_model_frame>1</use_parent_model_frame>
      </axis>
    </joint>
    <link name='shoulder_thigh_fr_1'>
      <pose frame=''>-0.02 -0.2175 0.016285 0 -0 0</pose>
      <inertial>
        <pose frame=''>-0.035368 0.018568 -0 0 -0 0</pose>
        <mass>0.130474</mass>
        <inertia>
          <ixx>7.1e-05</ixx>
          <ixy>7e-06</ixy>
          <ixz>-0</ixz>
          <iyy>5.6e-05</iyy>
          <iyz>0</iyz>
          <izz>0.000123</izz>
        </inertia>
      </inertial>
      <collision name='shoulder_thigh_fr_1_collision'>
        <pose frame=''>0.02 0.2175 -0.016285 0 -0 0</pose>
        <geometry>
          <mesh>
            <scale>0.001 0.001 0.001</scale>
            <uri>model://simplicity_description/meshes/shoulder_thigh_fr_1.stl</uri>
          </mesh>
        </geometry>
        <surface>
          <contact>
            <ode/>
          </contact>
          <friction>
            <ode>
              <mu>0.2</mu>
              <mu2>0.2</mu2>
            </ode>
          </friction>
        </surface>
      </collision>
      <visual name='shoulder_thigh_fr_1_visual'>
        <pose frame=''>0.02 0.2175 -0.016285 0 -0 0</pose>
        <geometry>
          <mesh>
            <scale>0.001 0.001 0.001</scale>
            <uri>model://simplicity_description/meshes/shoulder_thigh_fr_1.stl</uri>
          </mesh>
        </geometry>
        <material>
          <script>
            <name>Gazebo/Silver</name>
            <uri>file://media/materials/scripts/gazebo.material</uri>
          </script>
        </material>
      </visual>
      <gravity>1</gravity>
      <velocity_decay/>
      <self_collide>1</self_collide>
    </link>
    <joint name='Rev14' type='revolute'>
      <child>shoulder_thigh_fr_1</child>
      <parent>base_link</parent>
      <axis>
        <xyz>0 -1 0</xyz>
        <limit>
          <lower>-1e+16</lower>
          <upper>1e+16</upper>
        </limit>
        <dynamics>
          <spring_reference>0</spring_reference>
          <spring_stiffness>0</spring_stiffness>
        </dynamics>
        <use_parent_model_frame>1</use_parent_model_frame>
      </axis>
    </joint>
    <link name='servo-thigh_fr_1'>
      <pose frame=''>-0.07975 -0.19495 0.016285 0 -0 0</pose>
      <inertial>
        <pose frame=''>-0.027076 0.035793 -0.035793 0 -0 0</pose>
        <mass>0.955761</mass>
        <inertia>
          <ixx>0.00189487</ixx>
          <ixy>3.15807e-05</ixy>
          <ixz>-3.15805e-05</ixz>
          <iyy>0.00102823</iyy>
          <iyz>0.000818937</iyz>
          <izz>0.00102823</izz>
        </inertia>
      </inertial>
      <collision name='servo-thigh_fr_1_collision'>
        <pose frame=''>0.07975 0.19495 -0.016285 0 -0 0</pose>
        <geometry>
          <mesh>
            <scale>0.001 0.001 0.001</scale>
            <uri>model://simplicity_description/meshes/servo-thigh_fr_1.stl</uri>
          </mesh>
        </geometry>
        <surface>
          <contact>
            <ode/>
          </contact>
          <friction>
            <ode>
              <mu>0.2</mu>
              <mu2>0.2</mu2>
            </ode>
          </friction>
        </surface>
      </collision>
      <collision name='servo-thigh_fr_1_fixed_joint_lump__thigh_fr_1_collision_1'>
        <pose frame=''>0.07975 0.19495 -0.016285 0 -0 0</pose>
        <geometry>
          <mesh>
            <scale>0.001 0.001 0.001</scale>
            <uri>model://simplicity_description/meshes/thigh_fr_1.stl</uri>
          </mesh>
        </geometry>
        <surface>
          <contact>
            <ode/>
          </contact>
          <friction>
            <ode>
              <mu>0.2</mu>
              <mu2>0.2</mu2>
            </ode>
          </friction>
        </surface>
      </collision>
      <collision name='servo-thigh_fr_1_fixed_joint_lump__servo_leg_fr_1_collision_2'>
        <pose frame=''>0.07975 0.19495 -0.016285 0 -0 0</pose>
        <geometry>
          <mesh>
            <scale>0.001 0.001 0.001</scale>
            <uri>model://simplicity_description/meshes/servo_leg_fr_1.stl</uri>
          </mesh>
        </geometry>
        <surface>
          <contact>
            <ode/>
          </contact>
          <friction>
            <ode>
              <mu>0.2</mu>
              <mu2>0.2</mu2>
            </ode>
          </friction>
        </surface>
      </collision>
      <collision name='servo-thigh_fr_1_fixed_joint_lump__servo_leg_back_fr_1_collision_3'>
        <pose frame=''>0.07975 0.19495 -0.016285 0 -0 0</pose>
        <geometry>
          <mesh>
            <scale>0.001 0.001 0.001</scale>
            <uri>model://simplicity_description/meshes/servo_leg_back_fr_1.stl</uri>
          </mesh>
        </geometry>
        <surface>
          <contact>
            <ode/>
          </contact>
          <friction>
            <ode>
              <mu>0.2</mu>
              <mu2>0.2</mu2>
            </ode>
          </friction>
        </surface>
      </collision>
      <visual name='servo-thigh_fr_1_visual'>
        <pose frame=''>0.07975 0.19495 -0.016285 0 -0 0</pose>
        <geometry>
          <mesh>
            <scale>0.001 0.001 0.001</scale>
            <uri>model://simplicity_description/meshes/servo-thigh_fr_1.stl</uri>
          </mesh>
        </geometry>
        <material>
          <script>
            <name>Gazebo/Silver</name>
            <uri>file://media/materials/scripts/gazebo.material</uri>
          </script>
        </material>
      </visual>
      <visual name='servo-thigh_fr_1_fixed_joint_lump__thigh_fr_1_visual_1'>
        <pose frame=''>0.07975 0.19495 -0.016285 0 -0 0</pose>
        <geometry>
          <mesh>
            <scale>0.001 0.001 0.001</scale>
            <uri>model://simplicity_description/meshes/thigh_fr_1.stl</uri>
          </mesh>
        </geometry>
        <material>
          <script>
            <name>Gazebo/Silver</name>
            <uri>file://media/materials/scripts/gazebo.material</uri>
          </script>
        </material>
      </visual>
      <visual name='servo-thigh_fr_1_fixed_joint_lump__servo_leg_fr_1_visual_2'>
        <pose frame=''>0.07975 0.19495 -0.016285 0 -0 0</pose>
        <geometry>
          <mesh>
            <scale>0.001 0.001 0.001</scale>
            <uri>model://simplicity_description/meshes/servo_leg_fr_1.stl</uri>
          </mesh>
        </geometry>
        <material>
          <script>
            <name>Gazebo/Silver</name>
            <uri>file://media/materials/scripts/gazebo.material</uri>
          </script>
        </material>
      </visual>
      <visual name='servo-thigh_fr_1_fixed_joint_lump__servo_leg_back_fr_1_visual_3'>
        <pose frame=''>0.07975 0.19495 -0.016285 0 -0 0</pose>
        <geometry>
          <mesh>
            <scale>0.001 0.001 0.001</scale>
            <uri>model://simplicity_description/meshes/servo_leg_back_fr_1.stl</uri>
          </mesh>
        </geometry>
        <material>
          <script>
            <name>Gazebo/Silver</name>
            <uri>file://media/materials/scripts/gazebo.material</uri>
          </script>
        </material>
      </visual>
      <velocity_decay/>
      <velocity_decay/>
      <velocity_decay/>
      <gravity>1</gravity>
      <velocity_decay/>
      <self_collide>1</self_collide>
    </link>
    <joint name='Rev19' type='revolute'>
      <child>servo-thigh_fr_1</child>
      <parent>shoulder_thigh_fr_1</parent>
      <axis>
        <xyz>1 0 0</xyz>
        <limit>
          <lower>-1e+16</lower>
          <upper>1e+16</upper>
        </limit>
        <dynamics>
          <spring_reference>0</spring_reference>
          <spring_stiffness>0</spring_stiffness>
        </dynamics>
        <use_parent_model_frame>1</use_parent_model_frame>
      </axis>
    </joint>
    <link name='thigh_leg_fr_1'>
      <pose frame=''>-0.13475 -0.125349 -0.053316 0 -0 0</pose>
      <inertial>
        <pose frame=''>0.020704 -0.033398 -0.061378 0 -0 0</pose>
        <mass>0.28447</mass>
        <inertia>
          <ixx>0.000444752</ixx>
          <ixy>1.14128e-05</ixy>
          <ixz>2.12883e-05</ixz>
          <iyy>0.000430158</iyy>
          <iyz>-0.000175334</iyz>
          <izz>0.000170068</izz>
        </inertia>
      </inertial>
      <collision name='thigh_leg_fr_1_collision'>
        <pose frame=''>0.13475 0.125349 0.053316 0 -0 0</pose>
        <geometry>
          <mesh>
            <scale>0.001 0.001 0.001</scale>
            <uri>model://simplicity_description/meshes/thigh_leg_fr_1.stl</uri>
          </mesh>
        </geometry>
        <surface>
          <contact>
            <ode/>
          </contact>
          <friction>
            <ode>
              <mu>0.2</mu>
              <mu2>0.2</mu2>
            </ode>
          </friction>
        </surface>
      </collision>
      <collision name='thigh_leg_fr_1_fixed_joint_lump__contact_sensor_fr_1_collision_1'>
        <pose frame=''>0.13475 0.125349 0.053316 0 -0 0</pose>
        <geometry>
          <mesh>
            <scale>0.001 0.001 0.001</scale>
            <uri>model://simplicity_description/meshes/contact_sensor_fr_1.stl</uri>
          </mesh>
        </geometry>
        <surface>
          <contact>
            <ode>
              <kp>1e+06</kp>
              <kd>1e+06</kd>
            </ode>
          </contact>
          <friction>
            <ode>
              <mu>1e+06</mu>
              <mu2>1e+06</mu2>
            </ode>
          </friction>
        </surface>
      </collision>
      <collision name='thigh_leg_fr_1_fixed_joint_lump__leg_fr_1_collision_2'>
        <pose frame=''>0.13475 0.125349 0.053316 0 -0 0</pose>
        <geometry>
          <mesh>
            <scale>0.001 0.001 0.001</scale>
            <uri>model://simplicity_description/meshes/leg_fr_1.stl</uri>
          </mesh>
        </geometry>
        <surface>
          <contact>
            <ode/>
          </contact>
          <friction>
            <ode>
              <mu>0.2</mu>
              <mu2>0.2</mu2>
            </ode>
          </friction>
        </surface>
      </collision>
      <visual name='thigh_leg_fr_1_visual'>
        <pose frame=''>0.13475 0.125349 0.053316 0 -0 0</pose>
        <geometry>
          <mesh>
            <scale>0.001 0.001 0.001</scale>
            <uri>model://simplicity_description/meshes/thigh_leg_fr_1.stl</uri>
          </mesh>
        </geometry>
        <material>
          <script>
            <name>Gazebo/Silver</name>
            <uri>file://media/materials/scripts/gazebo.material</uri>
          </script>
        </material>
      </visual>
      <visual name='thigh_leg_fr_1_fixed_joint_lump__contact_sensor_fr_1_visual_1'>
        <pose frame=''>0.13475 0.125349 0.053316 0 -0 0</pose>
        <geometry>
          <mesh>
            <scale>0.001 0.001 0.001</scale>
            <uri>model://simplicity_description/meshes/contact_sensor_fr_1.stl</uri>
          </mesh>
        </geometry>
        <material>
          <script>
            <name>Gazebo/Blue</name>
            <uri>file://media/materials/scripts/gazebo.material</uri>
          </script>
        </material>
      </visual>
      <visual name='thigh_leg_fr_1_fixed_joint_lump__leg_fr_1_visual_2'>
        <pose frame=''>0.13475 0.125349 0.053316 0 -0 0</pose>
        <geometry>
          <mesh>
            <scale>0.001 0.001 0.001</scale>
            <uri>model://simplicity_description/meshes/leg_fr_1.stl</uri>
          </mesh>
        </geometry>
        <material>
          <script>
            <name>Gazebo/Silver</name>
            <uri>file://media/materials/scripts/gazebo.material</uri>
          </script>
        </material>
      </visual>
      <velocity_decay/>
      <velocity_decay/>
      <velocity_decay/>
      <sensor name='contactsensor_sensor' type='contact'>
        <always_on>1</always_on>
        <contact>
          <collision>contact_sensor_fr_1_collision_1</collision>
          <topic>__default_topic__</topic>
        </contact>
        <plugin name='bumper0_plugin' filename='libgazebo_ros_bumper.so'>
          <bumperTopicName>front_right_contact_sensor_state</bumperTopicName>
          <frameName>contact_sensor_fr_1</frameName>
        </plugin>
        <pose frame=''>0.032393 -0.028468 -0.049356 0 -0 0</pose>
      </sensor>
      <gravity>1</gravity>
      <velocity_decay/>
      <self_collide>1</self_collide>
    </link>
    <joint name='Rev36' type='revolute'>
      <child>thigh_leg_fr_1</child>
      <parent>servo-thigh_fr_1</parent>
      <axis>
        <xyz>-1 0 0</xyz>
        <limit>
          <lower>-1e+16</lower>
          <upper>1e+16</upper>
        </limit>
        <dynamics>
          <spring_reference>0</spring_reference>
          <spring_stiffness>0</spring_stiffness>
        </dynamics>
        <use_parent_model_frame>1</use_parent_model_frame>
      </axis>
    </joint>
    <link name='shoulder_thigh_br_1'>
      <pose frame=''>-0.02 0.2075 0.016284 0 -0 0</pose>
      <inertial>
        <pose frame=''>-0.035368 -0.018568 0 0 -0 0</pose>
        <mass>0.130474</mass>
        <inertia>
          <ixx>7.1e-05</ixx>
          <ixy>-7e-06</ixy>
          <ixz>0</ixz>
          <iyy>5.6e-05</iyy>
          <iyz>0</iyz>
          <izz>0.000123</izz>
        </inertia>
      </inertial>
      <collision name='shoulder_thigh_br_1_collision'>
        <pose frame=''>0.02 -0.2075 -0.016284 0 -0 0</pose>
        <geometry>
          <mesh>
            <scale>0.001 0.001 0.001</scale>
            <uri>model://simplicity_description/meshes/shoulder_thigh_br_1.stl</uri>
          </mesh>
        </geometry>
        <surface>
          <contact>
            <ode/>
          </contact>
          <friction>
            <ode>
              <mu>0.2</mu>
              <mu2>0.2</mu2>
            </ode>
          </friction>
        </surface>
      </collision>
      <visual name='shoulder_thigh_br_1_visual'>
        <pose frame=''>0.02 -0.2075 -0.016284 0 -0 0</pose>
        <geometry>
          <mesh>
            <scale>0.001 0.001 0.001</scale>
            <uri>model://simplicity_description/meshes/shoulder_thigh_br_1.stl</uri>
          </mesh>
        </geometry>
        <material>
          <script>
            <name>Gazebo/Silver</name>
            <uri>file://media/materials/scripts/gazebo.material</uri>
          </script>
        </material>
      </visual>
      <gravity>1</gravity>
      <velocity_decay/>
      <self_collide>1</self_collide>
    </link>
    <joint name='Rev17' type='revolute'>
      <child>shoulder_thigh_br_1</child>
      <parent>base_link</parent>
      <axis>
        <xyz>0 1 0</xyz>
        <limit>
          <lower>-1e+16</lower>
          <upper>1e+16</upper>
        </limit>
        <dynamics>
          <spring_reference>0</spring_reference>
          <spring_stiffness>0</spring_stiffness>
        </dynamics>
        <use_parent_model_frame>1</use_parent_model_frame>
      </axis>
    </joint>
    <link name='servo_thigh_br_1'>
      <pose frame=''>-0.07975 0.18495 0.016284 0 -0 0</pose>
      <inertial>
        <pose frame=''>-0.027076 0.035793 -0.035793 0 -0 0</pose>
        <mass>0.955761</mass>
        <inertia>
          <ixx>0.00189487</ixx>
          <ixy>3.15805e-05</ixy>
          <ixz>-3.15807e-05</ixz>
          <iyy>0.00102823</iyy>
          <iyz>0.000818937</iyz>
          <izz>0.00102823</izz>
        </inertia>
      </inertial>
      <collision name='servo_thigh_br_1_collision'>
        <pose frame=''>0.07975 -0.18495 -0.016284 0 -0 0</pose>
        <geometry>
          <mesh>
            <scale>0.001 0.001 0.001</scale>
            <uri>model://simplicity_description/meshes/servo_thigh_br_1.stl</uri>
          </mesh>
        </geometry>
        <surface>
          <contact>
            <ode/>
          </contact>
          <friction>
            <ode>
              <mu>0.2</mu>
              <mu2>0.2</mu2>
            </ode>
          </friction>
        </surface>
      </collision>
      <collision name='servo_thigh_br_1_fixed_joint_lump__thigh_br_1_collision_1'>
        <pose frame=''>0.07975 -0.18495 -0.016284 0 -0 0</pose>
        <geometry>
          <mesh>
            <scale>0.001 0.001 0.001</scale>
            <uri>model://simplicity_description/meshes/thigh_br_1.stl</uri>
          </mesh>
        </geometry>
        <surface>
          <contact>
            <ode/>
          </contact>
          <friction>
            <ode>
              <mu>0.2</mu>
              <mu2>0.2</mu2>
            </ode>
          </friction>
        </surface>
      </collision>
      <collision name='servo_thigh_br_1_fixed_joint_lump__servo_leg_br_1_collision_2'>
        <pose frame=''>0.07975 -0.18495 -0.016284 0 -0 0</pose>
        <geometry>
          <mesh>
            <scale>0.001 0.001 0.001</scale>
            <uri>model://simplicity_description/meshes/servo_leg_br_1.stl</uri>
          </mesh>
        </geometry>
        <surface>
          <contact>
            <ode/>
          </contact>
          <friction>
            <ode>
              <mu>0.2</mu>
              <mu2>0.2</mu2>
            </ode>
          </friction>
        </surface>
      </collision>
      <collision name='servo_thigh_br_1_fixed_joint_lump__servo_leg_back_br_1_collision_3'>
        <pose frame=''>0.07975 -0.18495 -0.016284 0 -0 0</pose>
        <geometry>
          <mesh>
            <scale>0.001 0.001 0.001</scale>
            <uri>model://simplicity_description/meshes/servo_leg_back_br_1.stl</uri>
          </mesh>
        </geometry>
        <surface>
          <contact>
            <ode/>
          </contact>
          <friction>
            <ode>
              <mu>0.2</mu>
              <mu2>0.2</mu2>
            </ode>
          </friction>
        </surface>
      </collision>
      <visual name='servo_thigh_br_1_visual'>
        <pose frame=''>0.07975 -0.18495 -0.016284 0 -0 0</pose>
        <geometry>
          <mesh>
            <scale>0.001 0.001 0.001</scale>
            <uri>model://simplicity_description/meshes/servo_thigh_br_1.stl</uri>
          </mesh>
        </geometry>
        <material>
          <script>
            <name>Gazebo/Silver</name>
            <uri>file://media/materials/scripts/gazebo.material</uri>
          </script>
        </material>
      </visual>
      <visual name='servo_thigh_br_1_fixed_joint_lump__thigh_br_1_visual_1'>
        <pose frame=''>0.07975 -0.18495 -0.016284 0 -0 0</pose>
        <geometry>
          <mesh>
            <scale>0.001 0.001 0.001</scale>
            <uri>model://simplicity_description/meshes/thigh_br_1.stl</uri>
          </mesh>
        </geometry>
        <material>
          <script>
            <name>Gazebo/Silver</name>
            <uri>file://media/materials/scripts/gazebo.material</uri>
          </script>
        </material>
      </visual>
      <visual name='servo_thigh_br_1_fixed_joint_lump__servo_leg_br_1_visual_2'>
        <pose frame=''>0.07975 -0.18495 -0.016284 0 -0 0</pose>
        <geometry>
          <mesh>
            <scale>0.001 0.001 0.001</scale>
            <uri>model://simplicity_description/meshes/servo_leg_br_1.stl</uri>
          </mesh>
        </geometry>
        <material>
          <script>
            <name>Gazebo/Silver</name>
            <uri>file://media/materials/scripts/gazebo.material</uri>
          </script>
        </material>
      </visual>
      <visual name='servo_thigh_br_1_fixed_joint_lump__servo_leg_back_br_1_visual_3'>
        <pose frame=''>0.07975 -0.18495 -0.016284 0 -0 0</pose>
        <geometry>
          <mesh>
            <scale>0.001 0.001 0.001</scale>
            <uri>model://simplicity_description/meshes/servo_leg_back_br_1.stl</uri>
          </mesh>
        </geometry>
        <material>
          <script>
            <name>Gazebo/Silver</name>
            <uri>file://media/materials/scripts/gazebo.material</uri>
          </script>
        </material>
      </visual>
      <velocity_decay/>
      <velocity_decay/>
      <velocity_decay/>
      <gravity>1</gravity>
      <velocity_decay/>
      <self_collide>1</self_collide>
    </link>
    <joint name='Rev20' type='revolute'>
      <child>servo_thigh_br_1</child>
      <parent>shoulder_thigh_br_1</parent>
      <axis>
        <xyz>1 0 0</xyz>
        <limit>
          <lower>-1e+16</lower>
          <upper>1e+16</upper>
        </limit>
        <dynamics>
          <spring_reference>0</spring_reference>
          <spring_stiffness>0</spring_stiffness>
        </dynamics>
        <use_parent_model_frame>1</use_parent_model_frame>
      </axis>
    </joint>
    <link name='thigh_leg_br_1'>
      <pose frame=''>-0.13475 0.254551 -0.053317 0 -0 0</pose>
      <inertial>
        <pose frame=''>0.020704 -0.033398 -0.061377 0 -0 0</pose>
        <mass>0.28447</mass>
        <inertia>
          <ixx>0.000444753</ixx>
          <ixy>1.14128e-05</ixy>
          <ixz>2.12883e-05</ixz>
          <iyy>0.000430159</iyy>
          <iyz>-0.000175334</iyz>
          <izz>0.000170068</izz>
        </inertia>
      </inertial>
      <collision name='thigh_leg_br_1_collision'>
        <pose frame=''>0.13475 -0.254551 0.053317 0 -0 0</pose>
        <geometry>
          <mesh>
            <scale>0.001 0.001 0.001</scale>
            <uri>model://simplicity_description/meshes/thigh_leg_br_1.stl</uri>
          </mesh>
        </geometry>
        <surface>
          <contact>
            <ode/>
          </contact>
          <friction>
            <ode>
              <mu>0.2</mu>
              <mu2>0.2</mu2>
            </ode>
          </friction>
        </surface>
      </collision>
      <collision name='thigh_leg_br_1_fixed_joint_lump__contact_sensor_br_1_collision_1'>
        <pose frame=''>0.13475 -0.254551 0.053317 0 -0 0</pose>
        <geometry>
          <mesh>
            <scale>0.001 0.001 0.001</scale>
            <uri>model://simplicity_description/meshes/contact_sensor_br_1.stl</uri>
          </mesh>
        </geometry>
        <surface>
          <contact>
            <ode>
              <kp>1e+06</kp>
              <kd>1e+06</kd>
            </ode>
          </contact>
          <friction>
            <ode>
              <mu>1e+06</mu>
              <mu2>1e+06</mu2>
            </ode>
          </friction>
        </surface>
      </collision>
      <collision name='thigh_leg_br_1_fixed_joint_lump__leg_br_1_collision_2'>
        <pose frame=''>0.13475 -0.254551 0.053317 0 -0 0</pose>
        <geometry>
          <mesh>
            <scale>0.001 0.001 0.001</scale>
            <uri>model://simplicity_description/meshes/leg_br_1.stl</uri>
          </mesh>
        </geometry>
        <surface>
          <contact>
            <ode/>
          </contact>
          <friction>
            <ode>
              <mu>0.2</mu>
              <mu2>0.2</mu2>
            </ode>
          </friction>
        </surface>
      </collision>
      <visual name='thigh_leg_br_1_visual'>
        <pose frame=''>0.13475 -0.254551 0.053317 0 -0 0</pose>
        <geometry>
          <mesh>
            <scale>0.001 0.001 0.001</scale>
            <uri>model://simplicity_description/meshes/thigh_leg_br_1.stl</uri>
          </mesh>
        </geometry>
        <material>
          <script>
            <name>Gazebo/Silver</name>
            <uri>file://media/materials/scripts/gazebo.material</uri>
          </script>
        </material>
      </visual>
      <visual name='thigh_leg_br_1_fixed_joint_lump__contact_sensor_br_1_visual_1'>
        <pose frame=''>0.13475 -0.254551 0.053317 0 -0 0</pose>
        <geometry>
          <mesh>
            <scale>0.001 0.001 0.001</scale>
            <uri>model://simplicity_description/meshes/contact_sensor_br_1.stl</uri>
          </mesh>
        </geometry>
        <material>
          <script>
            <name>Gazebo/Blue</name>
            <uri>file://media/materials/scripts/gazebo.material</uri>
          </script>
        </material>
      </visual>
      <visual name='thigh_leg_br_1_fixed_joint_lump__leg_br_1_visual_2'>
        <pose frame=''>0.13475 -0.254551 0.053317 0 -0 0</pose>
        <geometry>
          <mesh>
            <scale>0.001 0.001 0.001</scale>
            <uri>model://simplicity_description/meshes/leg_br_1.stl</uri>
          </mesh>
        </geometry>
        <material>
          <script>
            <name>Gazebo/Silver</name>
            <uri>file://media/materials/scripts/gazebo.material</uri>
          </script>
        </material>
      </visual>
      <velocity_decay/>
      <velocity_decay/>
      <velocity_decay/>
      <sensor name='contactsensor_sensor' type='contact'>
        <always_on>1</always_on>
        <contact>
          <collision>contact_sensor_br_1_collision_1</collision>
          <topic>__default_topic__</topic>
        </contact>
        <plugin name='bumper0_plugin' filename='libgazebo_ros_bumper.so'>
          <bumperTopicName>back_right_contact_sensor_state</bumperTopicName>
          <frameName>contact_sensor_br_1</frameName>
        </plugin>
        <pose frame=''>0.032393 -0.028468 -0.049355 0 -0 0</pose>
      </sensor>
      <gravity>1</gravity>
      <velocity_decay/>
      <self_collide>1</self_collide>
    </link>
    <joint name='Rev38' type='revolute'>
      <child>thigh_leg_br_1</child>
      <parent>servo_thigh_br_1</parent>
      <axis>
        <xyz>-1 0 0</xyz>
        <limit>
          <lower>-1e+16</lower>
          <upper>1e+16</upper>
        </limit>
        <dynamics>
          <spring_reference>0</spring_reference>
          <spring_stiffness>0</spring_stiffness>
        </dynamics>
        <use_parent_model_frame>1</use_parent_model_frame>
      </axis>
    </joint>
    <link name='shoulder_thigh_bl_1'>
      <pose frame=''>0.02 0.2075 0.016303 0 -0 0</pose>
      <inertial>
        <pose frame=''>0.035369 -0.018568 0 0 -0 0</pose>
        <mass>0.130474</mass>
        <inertia>
          <ixx>7.1e-05</ixx>
          <ixy>7e-06</ixy>
          <ixz>0</ixz>
          <iyy>5.6e-05</iyy>
          <iyz>-0</iyz>
          <izz>0.000123</izz>
        </inertia>
      </inertial>
      <collision name='shoulder_thigh_bl_1_collision'>
        <pose frame=''>-0.02 -0.2075 -0.016303 0 -0 0</pose>
        <geometry>
          <mesh>
            <scale>0.001 0.001 0.001</scale>
            <uri>model://simplicity_description/meshes/shoulder_thigh_bl_1.stl</uri>
          </mesh>
        </geometry>
        <surface>
          <contact>
            <ode/>
          </contact>
          <friction>
            <ode>
              <mu>0.2</mu>
              <mu2>0.2</mu2>
            </ode>
          </friction>
        </surface>
      </collision>
      <visual name='shoulder_thigh_bl_1_visual'>
        <pose frame=''>-0.02 -0.2075 -0.016303 0 -0 0</pose>
        <geometry>
          <mesh>
            <scale>0.001 0.001 0.001</scale>
            <uri>model://simplicity_description/meshes/shoulder_thigh_bl_1.stl</uri>
          </mesh>
        </geometry>
        <material>
          <script>
            <name>Gazebo/Silver</name>
            <uri>file://media/materials/scripts/gazebo.material</uri>
          </script>
        </material>
      </visual>
      <gravity>1</gravity>
      <velocity_decay/>
      <self_collide>1</self_collide>
    </link>
    <joint name='Rev16' type='revolute'>
      <child>shoulder_thigh_bl_1</child>
      <parent>base_link</parent>
      <axis>
        <xyz>0 1 0</xyz>
        <limit>
          <lower>-1e+16</lower>
          <upper>1e+16</upper>
        </limit>
        <dynamics>
          <spring_reference>0</spring_reference>
          <spring_stiffness>0</spring_stiffness>
        </dynamics>
        <use_parent_model_frame>1</use_parent_model_frame>
      </axis>
    </joint>
    <link name='servo_thigh_bl_1'>
      <pose frame=''>0.07975 0.18495 0.016303 0 -0 0</pose>
      <inertial>
        <pose frame=''>0.027076 0.034443 -0.034443 0 -0 0</pose>
        <mass>0.955761</mass>
        <inertia>
          <ixx>0.00186191</ixx>
          <ixy>-3.07678e-05</ixy>
          <ixz>3.07676e-05</ixz>
          <iyy>0.00101174</iyy>
          <iyz>0.000802453</iyz>
          <izz>0.00101174</izz>
        </inertia>
      </inertial>
      <collision name='servo_thigh_bl_1_collision'>
        <pose frame=''>-0.07975 -0.18495 -0.016303 0 -0 0</pose>
        <geometry>
          <mesh>
            <scale>0.001 0.001 0.001</scale>
            <uri>model://simplicity_description/meshes/servo_thigh_bl_1.stl</uri>
          </mesh>
        </geometry>
        <surface>
          <contact>
            <ode/>
          </contact>
          <friction>
            <ode>
              <mu>0.2</mu>
              <mu2>0.2</mu2>
            </ode>
          </friction>
        </surface>
      </collision>
      <collision name='servo_thigh_bl_1_fixed_joint_lump__thigh_bl_1_collision_1'>
        <pose frame=''>-0.07975 -0.18495 -0.016303 0 -0 0</pose>
        <geometry>
          <mesh>
            <scale>0.001 0.001 0.001</scale>
            <uri>model://simplicity_description/meshes/thigh_bl_1.stl</uri>
          </mesh>
        </geometry>
        <surface>
          <contact>
            <ode/>
          </contact>
          <friction>
            <ode>
              <mu>0.2</mu>
              <mu2>0.2</mu2>
            </ode>
          </friction>
        </surface>
      </collision>
      <collision name='servo_thigh_bl_1_fixed_joint_lump__servo_leg_bl_1_collision_2'>
        <pose frame=''>-0.07975 -0.18495 -0.016303 0 -0 0</pose>
        <geometry>
          <mesh>
            <scale>0.001 0.001 0.001</scale>
            <uri>model://simplicity_description/meshes/servo_leg_bl_1.stl</uri>
          </mesh>
        </geometry>
        <surface>
          <contact>
            <ode/>
          </contact>
          <friction>
            <ode>
              <mu>0.2</mu>
              <mu2>0.2</mu2>
            </ode>
          </friction>
        </surface>
      </collision>
      <collision name='servo_thigh_bl_1_fixed_joint_lump__servo_leg_back_bl_1_collision_3'>
        <pose frame=''>-0.07975 -0.18495 -0.016303 0 -0 0</pose>
        <geometry>
          <mesh>
            <scale>0.001 0.001 0.001</scale>
            <uri>model://simplicity_description/meshes/servo_leg_back_bl_1.stl</uri>
          </mesh>
        </geometry>
        <surface>
          <contact>
            <ode/>
          </contact>
          <friction>
            <ode>
              <mu>0.2</mu>
              <mu2>0.2</mu2>
            </ode>
          </friction>
        </surface>
      </collision>
      <visual name='servo_thigh_bl_1_visual'>
        <pose frame=''>-0.07975 -0.18495 -0.016303 0 -0 0</pose>
        <geometry>
          <mesh>
            <scale>0.001 0.001 0.001</scale>
            <uri>model://simplicity_description/meshes/servo_thigh_bl_1.stl</uri>
          </mesh>
        </geometry>
        <material>
          <script>
            <name>Gazebo/Silver</name>
            <uri>file://media/materials/scripts/gazebo.material</uri>
          </script>
        </material>
      </visual>
      <visual name='servo_thigh_bl_1_fixed_joint_lump__thigh_bl_1_visual_1'>
        <pose frame=''>-0.07975 -0.18495 -0.016303 0 -0 0</pose>
        <geometry>
          <mesh>
            <scale>0.001 0.001 0.001</scale>
            <uri>model://simplicity_description/meshes/thigh_bl_1.stl</uri>
          </mesh>
        </geometry>
        <material>
          <script>
            <name>Gazebo/Silver</name>
            <uri>file://media/materials/scripts/gazebo.material</uri>
          </script>
        </material>
      </visual>
      <visual name='servo_thigh_bl_1_fixed_joint_lump__servo_leg_bl_1_visual_2'>
        <pose frame=''>-0.07975 -0.18495 -0.016303 0 -0 0</pose>
        <geometry>
          <mesh>
            <scale>0.001 0.001 0.001</scale>
            <uri>model://simplicity_description/meshes/servo_leg_bl_1.stl</uri>
          </mesh>
        </geometry>
        <material>
          <script>
            <name>Gazebo/Silver</name>
            <uri>file://media/materials/scripts/gazebo.material</uri>
          </script>
        </material>
      </visual>
      <visual name='servo_thigh_bl_1_fixed_joint_lump__servo_leg_back_bl_1_visual_3'>
        <pose frame=''>-0.07975 -0.18495 -0.016303 0 -0 0</pose>
        <geometry>
          <mesh>
            <scale>0.001 0.001 0.001</scale>
            <uri>model://simplicity_description/meshes/servo_leg_back_bl_1.stl</uri>
          </mesh>
        </geometry>
        <material>
          <script>
            <name>Gazebo/Silver</name>
            <uri>file://media/materials/scripts/gazebo.material</uri>
          </script>
        </material>
      </visual>
      <velocity_decay/>
      <velocity_decay/>
      <velocity_decay/>
      <gravity>1</gravity>
      <velocity_decay/>
      <self_collide>1</self_collide>
    </link>
    <joint name='Rev21' type='revolute'>
      <child>servo_thigh_bl_1</child>
      <parent>shoulder_thigh_bl_1</parent>
      <axis>
        <xyz>-1 0 0</xyz>
        <limit>
          <lower>-1e+16</lower>
          <upper>1e+16</upper>
        </limit>
        <dynamics>
          <spring_reference>0</spring_reference>
          <spring_stiffness>0</spring_stiffness>
        </dynamics>
        <use_parent_model_frame>1</use_parent_model_frame>
      </axis>
    </joint>
    <link name='thigh_leg_bl_1'>
      <pose frame=''>0.13475 0.252996 -0.051742 0 -0 0</pose>
      <inertial>
        <pose frame=''>-0.020846 -0.033398 -0.061378 0 -0 0</pose>
        <mass>0.28447</mass>
        <inertia>
          <ixx>0.000444752</ixx>
          <ixy>-1.19327e-05</ixy>
          <ixz>-2.232e-05</ixz>
          <iyy>0.000430302</iyy>
          <iyz>-0.000175334</iyz>
          <izz>0.000170212</izz>
        </inertia>
      </inertial>
      <collision name='thigh_leg_bl_1_collision'>
        <pose frame=''>-0.13475 -0.252996 0.051742 0 -0 0</pose>
        <geometry>
          <mesh>
            <scale>0.001 0.001 0.001</scale>
            <uri>model://simplicity_description/meshes/thigh_leg_bl_1.stl</uri>
          </mesh>
        </geometry>
        <surface>
          <contact>
            <ode/>
          </contact>
          <friction>
            <ode>
              <mu>0.2</mu>
              <mu2>0.2</mu2>
            </ode>
          </friction>
        </surface>
      </collision>
      <collision name='thigh_leg_bl_1_fixed_joint_lump__contact_sensor_bl_1_collision_1'>
        <pose frame=''>-0.13475 -0.252996 0.051742 0 -0 0</pose>
        <geometry>
          <mesh>
            <scale>0.001 0.001 0.001</scale>
            <uri>model://simplicity_description/meshes/contact_sensor_bl_1.stl</uri>
          </mesh>
        </geometry>
        <surface>
          <contact>
            <ode>
              <kp>1e+06</kp>
              <kd>1e+06</kd>
            </ode>
          </contact>
          <friction>
            <ode>
              <mu>1e+06</mu>
              <mu2>1e+06</mu2>
            </ode>
          </friction>
        </surface>
      </collision>
      <collision name='thigh_leg_bl_1_fixed_joint_lump__leg_bl_1_collision_2'>
        <pose frame=''>-0.13475 -0.252996 0.051742 0 -0 0</pose>
        <geometry>
          <mesh>
            <scale>0.001 0.001 0.001</scale>
            <uri>model://simplicity_description/meshes/leg_bl_1.stl</uri>
          </mesh>
        </geometry>
        <surface>
          <contact>
            <ode/>
          </contact>
          <friction>
            <ode>
              <mu>0.2</mu>
              <mu2>0.2</mu2>
            </ode>
          </friction>
        </surface>
      </collision>
      <visual name='thigh_leg_bl_1_visual'>
        <pose frame=''>-0.13475 -0.252996 0.051742 0 -0 0</pose>
        <geometry>
          <mesh>
            <scale>0.001 0.001 0.001</scale>
            <uri>model://simplicity_description/meshes/thigh_leg_bl_1.stl</uri>
          </mesh>
        </geometry>
        <material>
          <script>
            <name>Gazebo/Silver</name>
            <uri>file://media/materials/scripts/gazebo.material</uri>
          </script>
        </material>
      </visual>
      <visual name='thigh_leg_bl_1_fixed_joint_lump__contact_sensor_bl_1_visual_1'>
        <pose frame=''>-0.13475 -0.252996 0.051742 0 -0 0</pose>
        <geometry>
          <mesh>
            <scale>0.001 0.001 0.001</scale>
            <uri>model://simplicity_description/meshes/contact_sensor_bl_1.stl</uri>
          </mesh>
        </geometry>
        <material>
          <script>
            <name>Gazebo/Blue</name>
            <uri>file://media/materials/scripts/gazebo.material</uri>
          </script>
        </material>
      </visual>
      <visual name='thigh_leg_bl_1_fixed_joint_lump__leg_bl_1_visual_2'>
        <pose frame=''>-0.13475 -0.252996 0.051742 0 -0 0</pose>
        <geometry>
          <mesh>
            <scale>0.001 0.001 0.001</scale>
            <uri>model://simplicity_description/meshes/leg_bl_1.stl</uri>
          </mesh>
        </geometry>
        <material>
          <script>
            <name>Gazebo/Silver</name>
            <uri>file://media/materials/scripts/gazebo.material</uri>
          </script>
        </material>
      </visual>
      <velocity_decay/>
      <velocity_decay/>
      <velocity_decay/>
      <sensor name='contactsensor_sensor' type='contact'>
        <always_on>1</always_on>
        <contact>
          <collision>contact_sensor_bl_1_collision_1</collision>
          <topic>__default_topic__</topic>
        </contact>
        <plugin name='bumper0_plugin' filename='libgazebo_ros_bumper.so'>
          <bumperTopicName>back_left_contact_sensor_state</bumperTopicName>
          <frameName>contact_sensor_bl_1</frameName>
        </plugin>
        <pose frame=''>-0.012707 -0.028469 -0.049356 0 -0 0</pose>
      </sensor>
      <gravity>1</gravity>
      <velocity_decay/>
      <self_collide>1</self_collide>
    </link>
    <joint name='Rev37' type='revolute'>
      <child>thigh_leg_bl_1</child>
      <parent>servo_thigh_bl_1</parent>
      <axis>
        <xyz>1 0 0</xyz>
        <limit>
          <lower>-1e+16</lower>
          <upper>1e+16</upper>
        </limit>
        <dynamics>
          <spring_reference>0</spring_reference>
          <spring_stiffness>0</spring_stiffness>
        </dynamics>
        <use_parent_model_frame>1</use_parent_model_frame>
      </axis>
    </joint>
    <plugin name='control' filename='libgazebo_ros_control.so'>
      <robotNamespace>/simplicity</robotNamespace>
    </plugin>
    <plugin name='p3d_base_controller' filename='libgazebo_ros_p3d.so'>
      <alwaysOn>1</alwaysOn>
      <bodyName>base_link</bodyName>
      <topicName>odom</topicName>
      <gaussianNoise>0.01</gaussianNoise>
      <frameName>world</frameName>
      <xyzOffsets>0 0 0</xyzOffsets>
      <rpyOffsets>0 0 0</rpyOffsets>
    </plugin>
    <static>0</static>
    <plugin name='gazebo_ros_imu_controller' filename='libgazebo_ros_imu.so'>
      <robotNamespace>/simplicity</robotNamespace>
      <topicName>imu/data</topicName>
      <serviceName>imu/service</serviceName>
      <bodyName>base_link</bodyName>
      <gaussianNoise>0</gaussianNoise>
      <rpyOffsets>0 0 0</rpyOffsets>
      <alwaysOn>1</alwaysOn>
      <gaussianNoise>0</gaussianNoise>
    </plugin>
  </model>
</sdf>
